Workbook
Name Approach: [1]Parameters!$C$352:$C$354
Name Group: [1]Parameters!$C$317:$C$318
Name NERACA_1: #REF!
Name NERACA_1: #REF!
Name NERACA_1: #REF!
Name OpRiskApproach: [1]Parameters!$C$346:$C$347
Name YesNo: [1]Parameters!$C$315:$C$316

Sheet Summary
G2: LBU | H2: LHBU | I2: LKPBU | J2: LBBU | K2: LLD | L2: CF Data(V+)
D3: Total TORR Mandays : | E3: =#REF!+#REF!+#REF! -> #REF! | G3: =#REF! -> #REF! | H3: =#REF! -> #REF! | I3: =LKPBU!D1 -> 40 | J3: =LBBU!C2 -> 0 | K3: =#REF! -> #REF! | L3: ='CF Data(V+)'!D1 -> 0
D4: Total Finance Mandays : | E4: =#REF!+#REF!+LKPBU!C1+LBBU!C1+#REF!+'CF Data(V+)'!H10 -> #REF! | G4: =#REF! -> #REF! | H4: =#REF! -> #REF! | I4: =LKPBU!C1 -> 51 | J4: =LBBU!C1 -> 17 | K4: =#REF! -> #REF! | L4: ='CF Data(V+)'!H10 -> 0
D5: Total Mandays | E5: =E3+E4 -> #REF! | G5: =G3+G4 -> #REF! | H5: =H3+H4 -> #REF! | I5: =I3+I4 -> 91 | J5: =J3+J4 -> 17 | K5: =K3+K4 -> #REF! | L5: =L3+L4 -> 0
D7: Evaluate | G7: LBU | H7: LHBU | I7: LKPBU | J7: LBBU | K7: LLD | L7: CF Data(V+)
D8: Total TORR Mandays : | E8: =SUM(G8:L8) -> 108 | G8: 14 | H8: 19 | I8: 0 | J8: 0 | K8: 75 | L8: 0 | M8: ToRR : Harus ada buffer untuk scenario baru di budget proporsal
D9: Total Finance Mandays : | E9: =SUM(G9:L9) -> 96 | G9: 6 | H9: 29 | I9: 45 | J9: 16 | K9: 0 | L9: 0
D10: Total Mandays | E10: =SUM(E8:E9) -> 204 | G10: =SUM(G8:G9) -> 20 | H10: =SUM(H8:H9) -> 48 | I10: =SUM(I8:I9) -> 45 | J10: =SUM(J8:J9) -> 16 | K10: =SUM(K8:K9) -> 75 | L10: =SUM(L8:L9) -> 0

Sheet LKPBU
B1: Finance Mandays | C1: =SUMIF(D4:D12,"Finance",H4:H12) -> 51 | D1: 40
B2: SCOPE OF CR For Finance : | G2: 17-Mar-2016
A3: No | B3: Item | C3: Form | D3: Depart | E3: Status | F3: Detail Notes | G3: Notes | H3: Mandays | I3: Scope | J3: Out Of Scope
A4: 1 | B4: LKPBU - BS | C4: F901 | D4: Finance | E4: Fixing | F4: Additional new items from OJK | H4: 2 | I4: Only for : Additional new items from OJK update: identify new mapping and data source Maintenance screen for mapping in these forms (compare to LBU) Gap between LKPBU form and LBU form. 19. Pendapatan (kerugian) komprehensif lainnya-b. Keuntungan (kerugian) dari perubahan nilai aset keuangan dalam kelompok tersedia untuk dijual 19. Pendapatan (kerugian) komprehensif lainnya-f. Keuntungan (kerugian) aktuarial program imbalan pasti 19. Pendapatan (kerugian) komprehensif lainnya-g. Pajak penghasilan terkait dengan laba komprehensif lain | J4: any request that beyond of detail Scope CR
A5: =A4+1 -> 2 | B5: LKPBU - BS | C5: F902 | D5: Finance | E5: Fixing | F5: Additional new items from OJK | H5: 2 | I5: Only for : Additional new items from OJK update: identify new mapping and data source Maintenance screen for mapping in these forms (compare to LBU) Gap between LKPBU form and LBU form. 19. Pendapatan (kerugian) komprehensif lainnya-b. Keuntungan (kerugian) dari perubahan nilai aset keuangan dalam kelompok tersedia untuk dijual 19. Pendapatan (kerugian) komprehensif lainnya-f. Keuntungan (kerugian) aktuarial program imbalan pasti 19. Pendapatan (kerugian) komprehensif lainnya-g. Pajak penghasilan terkait dengan laba komprehensif lain | J5: any request that beyond of detail Scope CR
A6: =A5+1 -> 3 | B6: LKPBU - Laba Rugi | C6: F901 | D6: Finance | E6: Fixing | F6: Additional new items from OJK | H6: 4 | I6: Only for Additional new items from OJK update: identify new mapping and data source Maintenance screen for mapping in these forms (compare to LBU) Gap between LKPBU form and LBU form. 1. Pos-pos yang tidak akan direklasifikasi ke laba rugi b. Keuntungan (kerugian) aktuarial program imbalan pasti e. Pajak Penghasilan terkait pos-pos yang tidak akan direklasifikasi ke laba rugi 2. Pos-pos yang akan direklasifikasi ke laba rugi b. Keuntungan (kerugian) dari perubahan nilai aset keuangan dalam kelompok tersedia untuk dijual e. Pajak Penghasilan terkait pos-pos yang akan direklasifikasi ke laba rugi PENGHASILAN KOMPREHENSIF LAIN TAHUN BERJALAN - NET PAJAK PENGHASILAN TERKAIT TOTAL LABA (RUGI) KOMPREHENSIF TAHUN BERJALAN | J6: any request that beyond of detail Scope CR
A7: =A6+1 -> 4 | B7: LKPBU - Laba Rugi | C7: F902 | D7: Finance | E7: Fixing | F7: Additional new items from OJK | H7: 4 | I7: 1. Pos-pos yang tidak akan direklasifikasi ke laba rugi b. Keuntungan (kerugian) aktuarial program imbalan pasti e. Pajak Penghasilan terkait pos-pos yang tidak akan direklasifikasi ke laba rugi 2. Pos-pos yang akan direklasifikasi ke laba rugi b. Keuntungan (kerugian) dari perubahan nilai aset keuangan dalam kelompok tersedia untuk dijual e. Pajak Penghasilan terkait pos-pos yang akan direklasifikasi ke laba rugi 2. Pendapatan Komprehensif Lain tahun berjalan - net pajak penghasilan terkait 3. Total Laba Komprehensif Tahun Berjalan 4. Laba yang dapat diatribusikan kepada: - a. Pemilik 4. Laba yang dapat diatribusikan kepada: - c. Total Laba Tahun Berjalan 5. Total Laba Komprehensif Yang Dapat Diatribusikan Kepada: - a. Pemilik 5. Total Laba Komprehensif Yang Dapat Diatribusikan Kepada: - c. Total Laba Tahun Berjalan | J7: any request that beyond of detail Scope CR
A8: =A7+1 -> 5 | B8: F901-KPMM | C8: F901 | D8: Finance | E8: Fixing | F8: Additional new items from OJK | H8: 14 | I8: 1Modal Inti Utama (CET 1) 1.1Modal disetor (Setelah dikurangi Saham Treasury) 1.2Cadangan Tambahan Modal 1) 1.2.4Laba/Rugi tahun-tahun lalu yang dapat diperhitungkan 1.2.5Laba/Rugi tahun berjalan yang dapat diperhitungkan 1.2.10Pendapatan komprehensif lain 1.2.12Selisih kurang antara PPA dan cadangan kerugian penurunan nilai atas aset produktif 1.4Faktor Pengurang Modal Inti Utama 1) 1.4.1Perhitungan pajak tangguhan 1.4.3Aset tidak berwujud lainnya Modal Pelengkap (Tier 2) 1Instrumen modal dalam bentuk saham atau lainnya yang memenuhi persyaratan 3Cadangan umum aset produktif PPA yang wajib dibentuk (maks 1,25% ATMR Risiko Kredit) Total Modal Penambahan parameter table untuk ATMR Penambahan parameter table untuk PPA | J8: any request that beyond of detail Scope CR
A9: =A8+1 -> 6 | B9: F901-KAP | C9: F901 | D9: Finance | E9: Fixing | F9: Additional new items from OJK | H9: 5 | I9: Sandi A10A, Sandi B4A, Sandi B7A1, Sandi B7A2, Sandi B7B1, Sandi B7B2, New Sandi 10- Tagihan lainnya* | J9: any request that beyond of detail Scope CR
A10: =A9+1 -> 7 | B10: F902-KPMM | C10: F902 | D10: Finance | E10: Fixing | F10: Additional new items from OJK | H10: 14 | I10: Modal Inti (Tier 1) 1Modal Inti Utama (CET 1) 1.1Modal disetor (Setelah dikurangi Saham Treasury) 1.2Cadangan Tambahan Modal 1) 1.2.4Laba/Rugi tahun-tahun lalu yang dapat diperhitungkan 1.2.5Laba/Rugi tahun berjalan yang dapat diperhitungkan 1.2.10Pendapatan komprehensif lain 1.2.12Selisih kurang antara PPA dan cadangan kerugian penurunan nilai atas aset produktif 1.4Faktor Pengurang Modal Inti Utama 1) 1.4.1Perhitungan pajak tangguhan 1.4.3Aset tidak berwujud lainnya Modal Pelengkap (Tier 2) 1Instrumen modal dalam bentuk saham atau lainnya yang memenuhi persyaratan 3Cadangan umum aset produktif PPA yang wajib dibentuk (maks 1,25% ATMR Risiko Kredit) Total Modal Penambahan parameter table untuk ATMR Penambahan parameter table untuk PPA | J10: any request that beyond of detail Scope CR
A11: =A10+1 -> 8 | B11: F902-KAP | C11: F902 | D11: Finance | E11: Fixing | F11: Additional new items from OJK | H11: 5 | I11: Sandi A10A, Sandi B4A, Sandi B7A1, Sandi B7A2, Sandi B7B1, Sandi B7B2, New Sandi 10- Tagihan lainnya* | J11: any request that beyond of detail Scope CR
A12: =A11+1 -> 9 | B12: LKPBU - New Parameter Form for PPA on CKPN | C12: Parameter | D12: Finance | E12: Adding parameter form on Upload Process and display form | H12: 1 | I12: Only add new parameter Form for PPA and CKPN | J12: any request that beyond of detail Scope CR

Sheet LBBU
B1: Finance Mandays | C1: =SUM(G:H)+SUM(I4:I22) -> 17 | D1: 14
G2: 10-May-2016
A3: No | B3: Item | C3: Form | D3: Depart | E3: Jenis Enhancement | F3: Detail Enhancement BI | G3: Notes | H3: Mandays | I3: Scope /Assumption | J3: Out of Scope
A4: 1 | B4: remove form 6 and form 28, replace to form 42 | C4: Form12 | D4: Finance | E4: Enhancement Finance | F4: LBU Form 6 and LBU form 28 should be removed from report LBBU 12 and replaced by LBU form 42. You should filter “Variabel yang Mendasari” and take code 2 and 3 for the report. Tagihan Derivative should be reported in Aktiva side and Kewajiban Derivative should be reported in Pasiva side | G4: counterparty_cat in ('002','003') | H4: 5 | I4: only detail that already elaborate on enhancement field | J4: any request that not listed on enhancement field
A5: 2 | B5: add logic jenis on form 7 without interest rate | C5: Form12 | D5: Finance | E5: Enhancement Finance | F5: For LBU form 7, you only considered for “Jenis” without considered the interest rate” The following are Jenis Code in LBU form 7 which reported in LBBU form 12 as interest bearing: 042 SBI 043 BONDS 055 Acceptance Export Bills 057 Acceptance Export Bills 059 Acceptance Export Bills 082 BONDS 083 BONDS 086 BONDS 087 BONDS 044 SBI 061 BONDS | H5: 3 | I5: only detail that already elaborate on enhancement field | J5: any request that not listed on enhancement field
A6: 3 | B6: Reclass Form F0024, should only on Bucket < 1 month | C6: Form12 | D6: Finance | E6: Enhancement Finance | F6: Form 24 should be classified into bucket “A.< 1 bulan”, without considered the maturity date | H6: 2 | I6: only detail that already elaborate on enhancement field | J6: any request that not listed on enhancement field
A7: 4 | B7: enhancement logic for sandi 20790, 20700, 20600 | C7: 4A | D7: Finance | E7: Enhancement Finance | F7: Replace formula for sandi 20790, 20700, 20600 | H7: 0 | I7: There are no changing/revised formula that agreed ,tested, & implemented on Regla Application | J7: any request that not listed on enhancement field
A8: 5 | B8: enhancement logic for sandi 40100, 40200 | C8: 4A | D8: Finance | E8: Enhancement Finance | F8: Replace formula for sandi 40100, 40200 | H8: 0
A9: 6 | B9: enhancement logic for sandi 50100, 50130, 50132 | C9: 4A | D9: Finance | E9: Enhancement Finance | F9: Replace formula for sandi 50100, 50130, 50132 | H9: 0
A10: 7 | B10: enhancement logic for sandi 20790, 20700, 20600 | C10: 4B | D10: Finance | E10: Enhancement Finance | F10: Replace formula for sandi 20790, 20700, 20600 | H10: 0 | I10: There are no changing/revised formula that agreed ,tested, & implemented on Regla Application | J10: any request that not listed on enhancement field
A11: 8 | B11: enhancement logic for sandi 40100, 40200 | C11: 4B | D11: Finance | E11: Enhancement Finance | F11: Replace formula for sandi 40100, 40200 | H11: 0
A12: 9 | B12: enhancement logic for sandi 50100, 50130, 50132 | C12: 4B | D12: Finance | E12: Enhancement Finance | F12: Replace formula for sandi 50100, 50130, 50132 | H12: 0
A13: 10 | B13: add form f0042 to line 17,22 | C13: Form11 | D13: Finance | E13: Enhancement Finance | F13: Add form f0042 to line 17,22 | G13: counterparty_cat in ('002','003') | H13: 2 | I13: only detail that already elaborate on enhancement field | J13: any request that not listed on enhancement field
A14: 11 | B14: add product LC to line 38 | C14: Form11 | D14: Finance | E14: Enhancement Finance | F14: Add product LC to line 38 | H14: 2 | I14: only detail that already elaborate on enhancement field | J14: any request that not listed on enhancement field
A15: 12 | B15: add unused LC to line 72 | C15: Form11 | D15: Finance | E15: Enhancement Finance | F15: Add unused LC to line 72 | H15: 1 | I15: only detail that already elaborate on enhancement field | J15: any request that not listed on enhancement field
A16: 13 | B16: remove net off for line 27, and line 18 | C16: Form11 | D16: Finance | E16: Enhancement Finance | F16: Remove net off for line 27, and line 18 | H16: 2 | I16: only detail that already elaborate on enhancement field | J16: any request that not listed on enhancement field

Sheet Combine
D2: Project Setup / Kick Off
D3: Impact Analysis and User Requirement
D4: Dev
D5: SIT
D6: UAT
D7: Deployment UAT
D8: Deployment / Go Live
C11: Regla RR - Module LLLOJK - Enhancement CCS, CSO BMPK Detail Data LLLOJK & LLL Assessment Report
C12: Elapsed time (Week)
B13: Days | C13: Month1 | G13: Month2 | K13: Month3 | O13: Month4 | S13: Month5
C14: 1 | D14: 2 | E14: 3 | F14: 4 | G14: 5 | H14: 6 | I14: 7 | J14: 8 | K14: 9 | L14: 10 | M14: 11 | N14: 12 | O14: 13 | P14: 14 | Q14: 15 | R14: 16 | S14: 17 | T14: 18 | U14: 19 | V14: 20
B15: 0
B16: 15 | C16: 5 | D16: 5 | E16: 5
B17: 33 | F17: 5 | G17: 5 | H17: 5 | I17: 5 | J17: 5 | K17: 5 | L17: 3
B18: 12 | L18: 2 | M18: 5 | N18: 5
B19: 18 | O19: 5 | P19: 5 | Q19: 5 | R19: 3
B20: 7 | R20: 2 | S20: 5
B21: 10 | T21: 5 | U21: 5
AD23: Role | AE23: MD | AF23: Rate | AG23: Cost | AH23: Buffer | AJ23: Role | AK23: Quo
A24: 18 | B24: PM | C24: 17 | AD24: PM | AE24: =SUM(C24:V24) -> 17 | AF24: 4000 | AG24: =AF24*AE24 -> 68000 | AH24: =110%*AE24 -> 18.7 | AJ24: PM | AK24: 12
A25: 20 | B25: TL | C25: 23 | AD25: TL | AE25: =SUM(C25:V25) -> 23 | AF25: 4000 | AG25: =AF25*AE25 -> 92000 | AH25: =110%*AE25 -> 25.3 | AJ25: TL | AK25: 12
A26: 57 | B26: BA | C26: 68 | AD26: BA | AE26: =SUM(C26:V26) -> 68 | AF26: 4000 | AG26: =AF26*AE26 -> 272000 | AH26: =110%*AE26 -> 74.8 | AJ26: BA | AK26: 35 | AM26: =AE26*8/5 -> 108.8
A27: 39 | B27: ETL | C27: 77 | AD27: ETL | AE27: =SUM(C27:V27) -> 77 | AF27: 4000 | AG27: =AF27*AE27 -> 308000 | AH27: =110%*AE27 -> 84.7 | AJ27: ETL | AK27: 60 | AM27: =AE27*8/5 -> 123.2
A28: 26 | B28: .NET | C28: 0 | AD28: .NET | AE28: =SUM(C28:V28) -> 0 | AF28: 4000 | AG28: =AF28*AE28 -> 0 | AH28: =110%*AE28 -> 0 | AJ28: .NET | AK28: 56 | AM28: =AE28*8/3 -> 0
A29: 12 | B29: QA | C29: 16 | AD29: QA | AE29: =SUM(C29:V29) -> 16 | AF29: 4000 | AG29: =AF29*AE29 -> 64000 | AH29: =110%*AE29 -> 17.6 | AJ29: QA | AK29: 15
B30: Overhead | AD30: Overhead | AE30: =SUM(C30:V30) -> 0 | AH30: =110%*AE30 -> 0
AD31: Total | AE31: =SUM(AE24:AE30) -> 201 | AG31: =SUM(AG24:AG30) -> 804000 | AH31: =SUM(AH24:AH30) -> 221.1 | AK31: =SUM(AK24:AK29) -> 190
AK32: =AK31*4000 -> 760000
B34: Legend | C34: Milestone | L34: Mandays | N34: Days | P34: PM | Q34: TL | R34: BA | S34: ETL | T34: .NET | U34: QA | V34: Mandays | X34: Check | Y34: Overday | Z34: OT + Meal Allowance + Transport | AG34: Regla RR - Module LLLOJK - Enhancement CCS, CSO BMPK Detail Data LLLOJK & LLL Assessment Report
C35: Project Setup / Kick Off | M35: 0 | O35: 0 | P35: 0 | Q35: 0 | R35: 0 | S35: 0 | T35: 0 | U35: 0 | W35: =SUM(P35:U35) -> 0 | X35: =M35=W35 -> TRUE | AE35: Milestone | AG35: Days | AH35: PD | AI35: PM | AJ35: TL | AK35: BA | AL35: ETL | AM35: NET | AN35: QA | AO35: # Res | AP35: MDs | AQ35: Remarks | AS35: PM | AT35: TL | AU35: BA | AV35: ETL | AW35: NET | AX35: QA | AZ35: PM | BA35: TL | BB35: BA | BC35: ETL | BD35: NET | BE35: QA
C36: Impact Analysis and User Requirement | M36: =W36 -> 29 | O36: =AG37 -> 15 | P36: 4 | Q36: 4 | R36: 14 | S36: 7 | T36: 0 | U36: 0 | W36: =SUM(P36:U36) -> 29 | X36: =M36=W36 -> TRUE | AE36: Project Setup | AG36: 0 | AI36: 0 | AJ36: 0 | AK36: 0 | AL36: 0 | AM36: 0 | AN36: 0 | AO36: 0 | AP36: 0
C37: Development | M37: =W37 -> 45 | O37: =AG38 -> 33 | P37: 6 | Q37: 6 | R37: 11 | S37: 22 | T37: 0 | U37: 0 | W37: =SUM(P37:U37) -> 45 | X37: =M37=W37 -> TRUE | AE37: Impact Analysis and User Requirement | AG37: =SUM(Detail!K20:L20) -> 15 | AI37: 0.25 | AJ37: 0.25 | AK37: 1 | AL37: 0.5 | AM37: 0 | AN37: 0 | AO37: =SUM(AI37:AN37) -> 2 | AP37: =ROUND(AO37*AG37,2) -> 30 | AS37: =ROUND(AI37*$AG37,2) -> 3.75 | AT37: =ROUND(AJ37*$AG37,2) -> 3.75 | AU37: =ROUND(AK37*$AG37,2) -> 15 | AV37: =ROUND(AL37*$AG37,2) -> 7.5 | AW37: =ROUND(AM37*$AG37,2) -> 0 | AX37: =ROUND(AN37*$AG37,2) -> 0 | AZ37: =ROUND(AS37,0) -> 4 | BA37: =ROUND(AT37,0) -> 4 | BB37: =ROUND(AU37,0) -> 15 | BC37: =ROUND(AV37,0) -> 8 | BD37: =ROUND(AW37,0) -> 0 | BE37: =ROUND(AX37,0) -> 0
C38: SIT (System Integration Test) | M38: =W38 -> 52 | O38: =AG39 -> 12 | P38: 4 | Q38: 4 | R38: 12 | S38: 16 | T38: 0 | U38: 16 | W38: =SUM(P38:U38) -> 52 | X38: =M38=W38 -> TRUE | AE38: Development | AG38: =SUM(Detail!M20:P20) -> 33 | AI38: 0.25 | AJ38: 0.25 | AK38: 0.5 | AL38: 1 | AM38: 0 | AN38: 0 | AO38: =SUM(AI38:AN38) -> 2 | AP38: =ROUND(AO38*AG38,2) -> 66 | AS38: =ROUND(AI38*$AG38,2) -> 8.25 | AT38: =ROUND(AJ38*$AG38,2) -> 8.25 | AU38: =ROUND(AK38*$AG38,2) -> 16.5 | AV38: =ROUND(AL38*$AG38,2) -> 33 | AW38: =ROUND(AM38*$AG38,2) -> 0 | AX38: =ROUND(AN38*$AG38,2) -> 0 | AZ38: =ROUND(AS38,0) -> 8 | BA38: =ROUND(AT38,0) -> 8 | BB38: =ROUND(AU38,0) -> 17 | BC38: =ROUND(AV38,0) -> 33 | BD38: =ROUND(AW38,0) -> 0 | BE38: =ROUND(AX38,0) -> 0
C39: UAT (User Acceptance Test) | M39: =W39 -> 40 | O39: =AG40 -> 18 | P39: 5 | Q39: 5 | R39: 20 | S39: 10 | T39: 0 | U39: 0 | W39: =SUM(P39:U39) -> 40 | X39: =M39=W39 -> TRUE | Y39: =(ROUND(0.5*O39,0)*3) -> 27 | AE39: SIT | AG39: =Detail!Q20 -> 12 | AI39: 0.25 | AJ39: 0.25 | AK39: 0.75 | AL39: 1 | AM39: 0 | AN39: 1 | AO39: =SUM(AI39:AN39) -> 3.25 | AP39: =ROUND(AO39*AG39,2) -> 39 | AS39: =ROUND(AI39*$AG39,2) -> 3 | AT39: =ROUND(AJ39*$AG39,2) -> 3 | AU39: =ROUND(AK39*$AG39,2) -> 9 | AV39: =ROUND(AL39*$AG39,2) -> 12 | AW39: =ROUND(AM39*$AG39,2) -> 0 | AX39: =ROUND(AN39*$AG39,2) -> 12 | AZ39: =ROUND(AS39,0) -> 3 | BA39: =ROUND(AT39,0) -> 3 | BB39: =ROUND(AU39,0) -> 9 | BC39: =ROUND(AV39,0) -> 12 | BD39: =ROUND(AW39,0) -> 0 | BE39: =ROUND(AX39,0) -> 12
C40: Deployment / Migration UAT | M40: =W40 -> 13 | O40: =AG41 -> 7 | P40: 0 | Q40: 2 | R40: 2 | S40: 9 | T40: 0 | U40: 0 | W40: =SUM(P40:U40) -> 13 | X40: =M40=W40 -> TRUE | Y40: =(ROUND(0.7 *O40,0)*3) -> 15 | AE40: UAT | AG40: =Detail!R20 -> 18 | AI40: 0.25 | AJ40: 0.25 | AK40: 1 | AL40: 0.5 | AM40: 0 | AN40: 0 | AO40: =SUM(AI40:AN40) -> 2 | AP40: =ROUND(AO40*AG40,2) -> 36 | AS40: =ROUND(AI40*$AG40,2) -> 4.5 | AT40: =ROUND(AJ40*$AG40,2) -> 4.5 | AU40: =ROUND(AK40*$AG40,2) -> 18 | AV40: =ROUND(AL40*$AG40,2) -> 9 | AW40: =ROUND(AM40*$AG40,2) -> 0 | AX40: =ROUND(AN40*$AG40,2) -> 0 | AZ40: =ROUND(AS40,0) -> 5 | BA40: =ROUND(AT40,0) -> 5 | BB40: =ROUND(AU40,0) -> 18 | BC40: =ROUND(AV40,0) -> 9 | BD40: =ROUND(AW40,0) -> 0 | BE40: =ROUND(AX40,0) -> 0
C41: Deployment / Migration Go Live | M41: =W41 -> 22 | O41: =AG42 -> 10 | P41: 2 | Q41: 2 | R41: 9 | S41: 9 | T41: 0 | U41: 0 | W41: =SUM(P41:U41) -> 22 | X41: =M41=W41 -> TRUE | AE41: SAT, OAT, Migration UAT | AG41: =Detail!S20 -> 7 | AI41: 0 | AJ41: 0.25 | AK41: 0.25 | AL41: 1 | AM41: 0 | AN41: 0 | AO41: =SUM(AI41:AN41) -> 1.5 | AP41: =ROUND(AO41*AG41,0) -> 11 | AS41: =ROUND(AI41*$AG41,2) -> 0 | AT41: =ROUND(AJ41*$AG41,2) -> 1.75 | AU41: =ROUND(AK41*$AG41,2) -> 1.75 | AV41: =ROUND(AL41*$AG41,2) -> 7 | AW41: =ROUND(AM41*$AG41,2) -> 0 | AX41: =ROUND(AN41*$AG41,2) -> 0 | AZ41: =ROUND(AS41,0) -> 0 | BA41: =ROUND(AT41,0) -> 2 | BB41: =ROUND(AU41,0) -> 2 | BC41: =ROUND(AV41,0) -> 7 | BD41: =ROUND(AW41,0) -> 0 | BE41: =ROUND(AX41,0) -> 0
C42: Total | M42: =SUM(M35:M41) -> 201 | O42: =SUM(O35:O41) -> 95 | P42: =SUM(P35:P41) -> 21 | Q42: =SUM(Q35:Q41) -> 23 | R42: =SUM(R35:R41) -> 68 | S42: =SUM(S35:S41) -> 73 | T42: =SUM(T35:T41) -> 0 | U42: =SUM(U35:U41) -> 16 | W42: =SUM(W35:W41) -> 201 | X42: =M42=W42 -> TRUE | Y42: =SUM(Y35:Y41) -> 42 | Z42: =Y42*(300000+100000+200000) -> 25200000 | AE42: SAT, OAT, Migration | AG42: =Detail!T20 -> 10 | AI42: 0.25 | AJ42: 0.25 | AK42: 1 | AL42: 1 | AM42: 0 | AN42: 0 | AO42: =SUM(AI42:AN42) -> 2.5 | AP42: =ROUND(AO42*AG42,0) -> 25 | AS42: =ROUND(AI42*$AG42,2) -> 2.5 | AT42: =ROUND(AJ42*$AG42,2) -> 2.5 | AU42: =ROUND(AK42*$AG42,2) -> 10 | AV42: =ROUND(AL42*$AG42,2) -> 10 | AW42: =ROUND(AM42*$AG42,2) -> 0 | AX42: =ROUND(AN42*$AG42,2) -> 0 | AZ42: =ROUND(AS42,0) -> 3 | BA42: =ROUND(AT42,0) -> 3 | BB42: =ROUND(AU42,0) -> 10 | BC42: =ROUND(AV42,0) -> 10 | BD42: =ROUND(AW42,0) -> 0 | BE42: =ROUND(AX42,0) -> 0
AG44: =SUM(AG36:AG43) -> 95 | AO44: =SUM(AO36:AO43) -> 13.25 | AP44: =SUM(AP36:AP43) -> 207
B46: Scope Of Work :
B47: Enhance to the reporting form as a result of : Enhancement CCS, CSO BMPK Detail Data LLLOJK & LLL Assessment Report (paste picture on cell AE47) | AZ47: =SUM(AZ37:BE42) -> 210 | BA47: =110%*AZ47 -> 231
...

Sheet Timeline
C2: Project Setup / Kick Off
C3: Impact Analysis and User Requirement
C4: Dev
C5: SIT
C6: UAT
C7: Deployment / Go Live
B9: Regla RR - Module LLLOJK - Enhancement CCS, CSO BMPK Detail Data LLLOJK & LLL Assessment Report
B10: Elapsed time (Week)
B11: Month1 | F11: Month2 | J11: Month3 | N11: Month4 | R11: Month5
B12: 1 | C12: 2 | D12: 3 | E12: 4 | F12: 5 | G12: 6 | H12: 7 | I12: 8 | J12: 9 | K12: 10 | L12: 11 | M12: 12 | N12: 13 | O12: 14 | P12: 15 | Q12: 16 | R12: 17 | S12: 18 | T12: 19 | U12: 20

Sheet Detail
A1: No | B1: Form | C1: Module | D1: Department | E1: Enhancement | F1: Detail Enhancement | G1: Notes | H1: Mandays | I1: Scope | J1: Out of Scope | K1: Ureq | M1: WEB | N1: ETL | Q1: SIT | R1: UAT | S1: LV UAT | T1: LV PROD | Y1: Ureq | AA1: WEB | AB1: ETL | AE1: SIT | AF1: UAT | AG1: LV UAT | AH1: LV PROD
K2: Ureq | L2: Doc | N2: DEV | O2: Code Review | P2: UT | Y2: Ureq | Z2: Doc | AB2: DEV | AC2: Code Review | AD2: UT
A3: 1 | B3: New Data Source - Nilai Agunan Diikat ke Fasilitas | C3: Antasena | D3: CPRAM/RRR | E3: Penambahan data source baru untuk kolom Nilai Agunan yang Diikat ke Fasilitas | F3: Penambahan source baru untuk kolom Nilai Agunan yang Diikat ke Fasilitas a. Penambahan table untuk data source baru untuk kolom Nilai Agunan yang Diikat ke Fasilitas b. Penambahan screen untuk data source baru untuk kolom Nilai Agunan yang Diikat ke Fasilitas c. Penambahan proses upload untuk data source baru untuk kolom Nilai Agunan yang Diikat ke Fasilitas | G3: File Source berupa excel | K3: 1 | L3: 1 | M3: 1 | N3: 2 | O3: 1 | P3: 2 | Q3: 2 | R3: 2 | T3: 2 | Y3: 1 | Z3: 1 | AA3: 1 | AB3: 2 | AC3: 1 | AD3: 2 | AE3: 2 | AF3: 2 | AG3: 1 | AH3: 2
A4: 2 | B4: Agunan Kredit/Pembiayaan (AKR01) | C4: Antasena | D4: CPRAM | E4: Penambahan dimensi “Nilai Agunan yang Diikat ke Fasilitas” | F4: 1. Penambahan kolom 'Nilai Agunan yang Diikat ke Fasilitas' pada table form AKR01 2. Penambahan kolom 'Nilai Agunan yang Diikat ke Fasilitas' pada screen form AKR01 3. Penambahan kolom 'Nilai Agunan yang Diikat ke Fasilitas' pada textfile form AKR01 4. Penambahan Validasi 'Nilai Agunan yang Diikat ke Fasilitas' masing-masing 'Nomor Agunan' tidak boleh lebih dari 'Nilai Agunan' yang dilaporkan di Informasi Agunan (agn01) 5. Penambahan transformasi proses baru untuk perhitungan 'Nilai Agunan yang Diikat ke Fasilitas' untuk keseluruhan form 6. Penambahan table dan screen hasil perhitungan 'Nilai Agunan yang Diikat ke Fasilitas' 7. Penambahan transformasi baru untuk Penambahan transformasi proses baru untuk update 'Nilai Agunan yang Diikat ke Fasilitas' pada form AKR01 8. Tidak ada perubahan mapping untuk form Agunan (agn01) | G4: Tidak tersedia kolom norek pada source baru Perhitungan prorate untuk Nilai Agunan diikat ke fasilitas berdasarkan CIF, COLL ID, LIMIT ID Saat ini pada AKR blm ada info limit ID Mapping akan sama dengan mapping kolom “Nilai Agunan yang Diikat ke Fasilitas” pada form AGA, GAG, ILA, AKA pada file 5 Module Antasena - Enhancement NEW LBUT - RRR | K4: 4 | L4: 2 | M4: 1 | N4: 5 | O4: 2 | P4: 3 | Q4: 4 | R4: 7 | S4: 4 | T4: 3 | Y4: 5 | Z4: 3 | AA4: 2 | AB4: 5 | AC4: 3 | AD4: 5 | AE4: 5 | AF4: 7 | AG4: 5 | AH4: 4
A5: 3 | B5: New Data Source - Pembiayaan Inclusif | C5: Antasena | D5: CPRAM/RRR | E5: Penambahan data source baru untuk kolom Pembiayaan Inclusif | F5: Penambahan data source baru untuk kolom Pembiayaan Inclusif Penambahan table untuk data source baru untuk kolom Pembiayaan Inclusif Penambahan screen untuk data source baru untuk kolom Pembiayaan Inclusif Penambahan proses upload untuk data source baru untuk kolom Pembiayaan Inclusif | G5: File source excel | K5: 1 | L5: 1 | M5: 1 | N5: 2 | O5: 1 | P5: 2 | Q5: 2 | R5: 2 | T5: 2 | Y5: 1 | Z5: 1 | AA5: 1 | AB5: 2 | AC5: 1 | AD5: 2 | AE5: 2 | AF5: 2 | AG5: 1 | AH5: 2
A6: 4 | B6: Kredit/Pembiayaan (KRP01) | C6: Antasena | D6: CPRAM | E6: Penambahan dimensi "Pembiayaan Inklusif" | F6: 1. Penambahan kolom 'Pembiayaan Inclusif' pada table form KRP01 2. Penambahan kolom 'Pembiayaan Inclusif' pada screen form KRP01 3. Penambahan kolom 'Pembiayaan Inclusif' pada textfile form KRP01 4. Penambahan mapping 'Pembiayaan Inclusif' pada form KRP01 5. Penambahan transformasi proses baru untuk perhitungan 'Pembiayaan Inclusif' 6. Penambahan transformasi proses baru untuk update 'Pembiayaan Inclusif' pada form KRP01 7. Penambahan commoncode baru untuk mapping 'Pembiayaan Inclusif' | G6: Tidak tersedia kolom norek pada source baru Pengenal pembayaran inclusif adalah berdasarkan limitID Mapping akan sama dengan mapping kolom “Pembiayaan Inclusif” pada form SYM, SBT pada file 5 Module Antasena - Enhancement NEW LBUT - RRR | K6: 3 | L6: 2 | M6: 1 | N6: 5 | O6: 1 | P6: 3 | Q6: 4 | R6: 7 | S6: 3 | T6: 3 | Y6: 3 | Z6: 2 | AA6: 2 | AB6: 5 | AC6: 3 | AD6: 5 | AE6: 5 | AF6: 7 | AG6: 5 | AH6: 4
A7: 5
K20: =SUM(K3:K19) -> 9 | L20: =SUM(L3:L19) -> 6 | M20: =SUM(M3:M19) -> 4 | N20: =SUM(N3:N19) -> 14 | O20: =SUM(O3:O19) -> 5 | P20: =SUM(P3:P19) -> 10 | Q20: =SUM(Q3:Q19) -> 12 | R20: =SUM(R3:R19) -> 18 | ... T20: =SUM(T3:T19) -> 10
N22: 20 | Q22: 15 | R22: 15

Sheet Detail Revamp Antasena
A1: No. | B1: Activities | D1: Remarks/Deliverables | E1: Man (PM + TL + DV) | F1: Days | G1: Mandays
B2: Requirement and Analysis | E2: ='[2]Revamp Antasena'!K14 -> 1.5 | F2: 1 | G2: =E2*F2 -> 1.5
C3: Gather requirements from user
C4: Analyze existing process
B5: Design
B6: LPS SCV - A2 Tingkat Bunga | C6: Design Data Model and Table Mapping (Source, Destination and Rule) | E6: ='[2]Revamp Antasena'!K15 -> 2 | F6: 1 | G6: =E6*F6 -> 2
B7: Development | G7: =E7*F7 -> 0
B9: LPS SCV - A2 Tingkat Bunga | C9: SQL : Add new logic for tingkat bunga field | E9: ='[2]Revamp Antasena'!K15 -> 2 | F9: 1 | G9: =E9*F9 -> 2
B11: SIT | D11: Test Result
B12: LPS SCV - A2 Tingkat Bunga | C12: - Upload Cashback parameter - Run the process through Web Application - Check Tingkat Bunga value - SIT Technical Documentation | E12: ='[2]Revamp Antasena'!K16 -> 3 | F12: 1 | G12: =E12*F12 -> 3
B14: UAT | D14: UAT Sign Off | E14: ='[2]Revamp Antasena'!K17 -> 3 | F14: 3 | G14: =E14*F14 -> 9
B15: MIGRATION | D15: Migration | E15: ='[2]Revamp Antasena'!K18 -> 2 | F15: 1 | G15: =E15*F15 -> 2
B16: UVT | D16: UVT | E16: ='[2]Revamp Antasena'!K19 -> 2 | F16: 1 | G16: =E16*F16 -> 2
B17: Total mandays | G17: =SUM(G2:G16) -> 21.5

Sheet CF Data(V+)
A2: No | B2: Detail No | C2: Form | D2: Module | E2: Department | F2: Enhancement | G2: Enhancement Type | H2: Mandays | I2: Scope | J2: Out Of Scope
H3: -
F10: Total Mandays | H10: =SUBTOTAL(9,H3:H8) -> 0
